Workbook

Sheet Learning_Data
A1: Learner_ID | B1: Learner_Name | C1: Department | D1: Region | E1: Course_Name | F1: Course_Category | G1: Assigned_Date | H1: Completion_Date | I1: Completion_Status | J1: Score_% | K1: Time_Spent_Hrs | L1: SLA_Days | M1: Actual_Days_Taken | N1: SLA_Met | O1: Manager_Name | P1: Quarter
A2: EMP1001 | B2: Aarav Shah | C2: Marketing | D2: APAC | E2: Compliance Basics | F2: Compliance | G2: 45798 | H2: 45802 | I2: Completed | J2: 94 | K2: 2.1 | L2: 14 | M2: 4 | N2: Yes | O2: Neha Verma | P2: Q2 2025
A3: EMP1002 | B3: Priya Nair | C3: Sales | D3: APAC | E3: Advanced Excel | F3: Technical | G3: 45769 | H3: 45770 | I3: Completed | J3: 95 | K3: 2.8 | L3: 14 | M3: 1 | N3: Yes | O3: Sunil Mehta | P3: Q2 2025
A4: EMP1003 | B4: Rohan Verma | C4: Finance | D4: EMEA | E4: Workplace Safety | F4: Compliance | G4: 45800 | H4: 45803 | I4: Completed | J4: 87 | K4: 3.7 | L4: 7 | M4: 3 | N4: Yes | O4: Priya Sharma | P4: Q2 2025
A5: EMP1004 | B5: Sneha Iyer | C5: Operations | D5: APAC | E5: Advanced Excel | F5: Technical | G5: 45705 | H5: 45728 | I5: Completed | J5: 98 | K5: 3.2 | L5: 30 | M5: 23 | N5: Yes | O5: Rajesh Kumar | P5: Q1 2025
A6: EMP1005 | B6: Karan Mehta | C6: Marketing | D6: EMEA | E6: Communication Skills | F6: Soft Skills | G6: 45721 | H6: 45740 | I6: Completed | J6: 100 | K6: 5.5 | L6: 30 | M6: 19 | N6: Yes | O6: Amit Singh | P6: Q1 2025
A7: EMP1006 | B7: Ananya Bose | C7: IT | D7: EMEA | E7: Advanced Excel | F7: Technical | G7: 45681 | H7: 45684 | I7: Completed | J7: 74 | K7: 7.1 | L7: 14 | M7: 3 | N7: Yes | O7: Neha Verma | P7: Q1 2025
A8: EMP1007 | B8: Vikram Rao | C8: HR | D8: EMEA | E8: Customer Service Excellence | F8: Soft Skills | G8: 45741 | H8: 45763 | I8: Completed | J8: 77 | K8: 6.1 | L8: 21 | M8: 22 | N8: No | O8: Rajesh Kumar | P8: Q1 2025
A9: EMP1008 | B9: Divya Pillai | C9: IT | D9: EMEA | E9: Communication Skills | F9: Soft Skills | G9: 45783 | H9: 45792 | I9: Completed | J9: 100 | K9: 6 | L9: 14 | M9: 9 | N9: Yes | O9: Priya Sharma | P9: Q2 2025
A10: EMP1009 | B10: Arjun Gupta | C10: Marketing | D10: APAC | E10: Compliance Basics | F10: Compliance | G10: 45775 | I10: In Progress | K10: 1.4 | L10: 7 | M10: 4 | N10: No | O10: Priya Sharma | P10: Q2 2025
A11: EMP1010 | B11: Meera Joshi | C11: IT | D11: APAC | E11: Data Privacy & GDPR | F11: Compliance | G11: 45913 | I11: In Progress | K11: 2.1 | L11: 30 | M11: 21 | N11: No | O11: Amit Singh | P11: Q3 2025
A12: EMP1011 | B12: Nikhil Patil | C12: Operations | D12: EMEA | E12: Communication Skills | F12: Soft Skills | G12: 45933 | H12: 45947 | I12: Completed | J12: 97 | K12: 4.1 | L12: 21 | M12: 14 | N12: Yes | O12: Priya Sharma | P12: Q4 2025
A13: EMP1012 | B13: Pooja Desai | C13: Operations | D13: APAC | E13: Workplace Safety | F13: Compliance | G13: 45704 | I13: In Progress | K13: 2.7 | L13: 7 | M13: 2 | N13: No | O13: Neha Verma | P13: Q1 2025
A14: EMP1013 | B14: Rahul Sharma | C14: IT | D14: APAC | E14: Agile Fundamentals | F14: Technical | G14: 45853 | H14: 45854 | I14: Completed | J14: 67 | K14: 5.9 | L14: 30 | M14: 1 | N14: Yes | O14: Sunil Mehta | P14: Q3 2025
A15: EMP1014 | B15: Shreya Kapoor | C15: Supply Chain | D15: APAC | E15: Customer Service Excellence | F15: Soft Skills | G15: 45715 | H15: 45730 | I15: Completed | J15: 60 | K15: 7.7 | L15: 21 | M15: 15 | N15: Yes | O15: Amit Singh | P15: Q1 2025
A16: EMP1015 | B16: Amit Tiwari | C16: IT | D16: EMEA | E16: Communication Skills | F16: Soft Skills | G16: 45712 | I16: In Progress | K16: 2.6 | L16: 21 | M16: 17 | N16: No | O16: Priya Sharma | P16: Q1 2025
A17: EMP1016 | B17: Kavita Reddy | C17: HR | D17: EMEA | E17: Communication Skills | F17: Soft Skills | G17: 45929 | H17: 45937 | I17: Completed | J17: 61 | K17: 2.2 | L17: 7 | M17: 8 | N17: No | O17: Amit Singh | P17: Q3 2025
A18: EMP1017 | B18: Suresh Naik | C18: Supply Chain | D18: APAC | E18: Data Privacy & GDPR | F18: Compliance | G18: 45687 | I18: In Progress | K18: 0.8 | L18: 14 | M18: 2 | N18: No | O18: Neha Verma | P18: Q1 2025
A19: EMP1018 | B19: Anjali Singh | C19: Supply Chain | D19: APAC | E19: Communication Skills | F19: Soft Skills | G19: 45722 | H19: 45740 | I19: Completed | J19: 70 | K19: 3.2 | L19: 14 | M19: 18 | N19: No | O19: Sunil Mehta | P19: Q1 2025
A20: EMP1019 | B20: Deepak Malhotra | C20: Finance | D20: EMEA | E20: Communication Skills | F20: Soft Skills | G20: 45760 | H20: 45782 | I20: Completed | J20: 83 | K20: 4.3 | L20: 21 | M20: 22 | N20: No | O20: Sunil Mehta | P20: Q2 2025
A21: EMP1020 | B21: Ritu Bansal | C21: Finance | D21: APAC | E21: Data Privacy & GDPR | F21: Compliance | G21: 45773 | H21: 45783 | I21: Completed | J21: 95 | K21: 3 | L21: 7 | M21: 10 | N21: No | O21: Priya Sharma | P21: Q2 2025
A22: EMP1021 | B22: Sanjay Dubey | C22: Sales | D22: APAC | E22: Compliance Basics | F22: Compliance | G22: 45775 | I22: Not Started | K22: 0.7 | L22: 7 | M22: 3 | N22: No | O22: Priya Sharma | P22: Q2 2025
A23: EMP1022 | B23: Nisha Agarwal | C23: HR | D23: EMEA | E23: Data Privacy & GDPR | F23: Compliance | G23: 45934 | H23: 45953 | I23: Completed | J23: 96 | K23: 4.6 | L23: 14 | M23: 19 | N23: No | O23: Neha Verma | P23: Q4 2025
A24: EMP1023 | B24: Tarun Chopra | C24: Supply Chain | D24: EMEA | E24: Data Privacy & GDPR | F24: Compliance | G24: 45706 | H24: 45712 | I24: Completed | J24: 87 | K24: 4.2 | L24: 7 | M24: 6 | N24: Yes | O24: Rajesh Kumar | P24: Q1 2025
A25: EMP1024 | B25: Pallavi Mishra | C25: Marketing | D25: APAC | E25: Compliance Basics | F25: Compliance | G25: 45864 | I25: In Progress | K25: 1.4 | L25: 21 | M25: 4 | N25: No | O25: Priya Sharma | P25: Q3 2025
A26: EMP1025 | B26: Yash Soni | C26: IT | D26: EMEA | E26: Project Management 101 | F26: Professional Dev | G26: 45874 | H26: 45882 | I26: Completed | J26: 64 | K26: 4.4 | L26: 14 | M26: 8 | N26: Yes | O26: Sunil Mehta | P26: Q3 2025
A27: EMP1026 | B27: Swati Kulkarni | C27: Sales | D27: APAC | E27: Communication Skills | F27: Soft Skills | G27: 45665 | I27: Not Started | K27: 1.1 | L27: 7 | M27: 2 | N27: No | O27: Neha Verma | P27: Q1 2025
A28: EMP1027 | B28: Manish Jain | C28: Finance | D28: EMEA | E28: Agile Fundamentals | F28: Technical | G28: 45688 | H28: 45701 | I28: Completed | J28: 76 | K28: 7.5 | L28: 14 | M28: 13 | N28: Yes | O28: Neha Verma | P28: Q1 2025
A29: EMP1028 | B29: Preeti Pandey | C29: HR | D29: EMEA | E29: Communication Skills | F29: Soft Skills | G29: 45907 | H29: 45914 | I29: Completed | J29: 63 | K29: 5.3 | L29: 14 | M29: 7 | N29: Yes | O29: Sunil Mehta | P29: Q3 2025
A30: EMP1029 | B30: Aditya Bhatt | C30: Sales | D30: APAC | E30: Compliance Basics | F30: Compliance | G30: 45683 | H30: 45717 | I30: Completed | J30: 70 | K30: 1.9 | L30: 30 | M30: 34 | N30: No | O30: Sunil Mehta | P30: Q1 2025
A31: EMP1030 | B31: Smita Doshi | C31: Sales | D31: EMEA | E31: Advanced Excel | F31: Technical | G31: 45692 | H31: 45711 | I31: Completed | J31: 75 | K31: 5.3 | L31: 14 | M31: 19 | N31: No | O31: Rajesh Kumar | P31: Q1 2025
A32: EMP1031 | B32: Rajat Saxena | C32: IT | D32: APAC | E32: Agile Fundamentals | F32: Technical | G32: 45956 | I32: Not Started | K32: 2.8 | L32: 21 | M32: 7 | N32: No | O32: Amit Singh | P32: Q4 2025
A33: EMP1032 | B33: Neelam Yadav | C33: Operations | D33: APAC | E33: Agile Fundamentals | F33: Technical | G33: 45725 | H33: 45750 | I33: Completed | J33: 64 | K33: 1.6 | L33: 21 | M33: 25 | N33: No | O33: Sunil Mehta | P33: Q1 2025
A34: EMP1033 | B34: Gaurav Thakur | C34: IT | D34: APAC | E34: Advanced Excel | F34: Technical | G34: 45933 | H34: 45938 | I34: Completed | J34: 82 | K34: 7.2 | L34: 14 | M34: 5 | N34: Yes | O34: Priya Sharma | P34: Q4 2025
A35: EMP1034 | B35: Sunita Choudhary | C35: HR | D35: APAC | E35: Project Management 101 | F35: Professional Dev | G35: 45882 | H35: 45908 | I35: Completed | J35: 93 | K35: 1.6 | L35: 21 | M35: 26 | N35: No | O35: Sunil Mehta | P35: Q3 2025
A36: EMP1035 | B36: Vivek Bhatia | C36: HR | D36: APAC | E36: Project Management 101 | F36: Professional Dev | G36: 45793 | I36: In Progress | K36: 2.4 | L36: 7 | M36: 6 | N36: No | O36: Amit Singh | P36: Q2 2025
A37: EMP1036 | B37: Rekha Shetty | C37: HR | D37: APAC | E37: Data Privacy & GDPR | F37: Compliance | G37: 45833 | H37: 45842 | I37: Completed | J37: 92 | K37: 4.7 | L37: 14 | M37: 9 | N37: Yes | O37: Rajesh Kumar | P37: Q2 2025
A38: EMP1037 | B38: Dinesh Patel | C38: Sales | D38: EMEA | E38: Leadership Essentials | F38: Leadership | G38: 45680 | H38: 45683 | I38: Completed | J38: 100 | K38: 7.9 | L38: 7 | M38: 3 | N38: Yes | O38: Priya Sharma | P38: Q1 2025
A39: EMP1038 | B39: Usha Menon | C39: Marketing | D39: EMEA | E39: Communication Skills | F39: Soft Skills | G39: 45876 | H39: 45888 | I39: Completed | J39: 69 | K39: 5 | L39: 7 | M39: 12 | N39: No | O39: Amit Singh | P39: Q3 2025
A40: EMP1039 | B40: Manoj Tripathi | C40: IT | D40: APAC | E40: Project Management 101 | F40: Professional Dev | G40: 45878 | H40: 45890 | I40: Completed | J40: 62 | K40: 7.3 | L40: 14 | M40: 12 | N40: Yes | O40: Priya Sharma | P40: Q3 2025
...

Sheet Summary_Dashboard
A1: 📊 Learning Analytics Summary Dashboard
A3: KPI | B3: Value
A4: Total Learners | B4: =COUNTA(Learning_Data!B2:B51) -> 50
A5: Total Courses Assigned | B5: =COUNTA(Learning_Data!E2:E51) -> 50
A6: Completion Rate % | B6: =COUNTIF(Learning_Data!I2:I51,"Completed")/COUNTA(Learning_Data!I2:I51)*100 -> 74
A7: SLA Met % | B7: =COUNTIF(Learning_Data!N2:N51,"Yes")/COUNTA(Learning_Data!N2:N51)*100 -> 48
A8: Avg Score % | B8: =AVERAGEIF(Learning_Data!J2:J51,">0") -> 81.837838
A9: Overdue Courses | B9: =COUNTIF(Learning_Data!I2:I51,"Overdue") -> 1
A10: Avg Time Spent (Hrs) | B10: =AVERAGE(Learning_Data!K2:K51) -> 3.932
A11: APAC Learners | B11: =COUNTIF(Learning_Data!D2:D51,"APAC") -> 28
A12: EMEA Learners | B12: =COUNTIF(Learning_Data!D2:D51,"EMEA") -> 22

Sheet Dept_Breakdown
A1: Department Breakdown
A3: Department | B3: Total Assigned | C3: Completed | D3: Completion Rate %
A4: Sales | B4: =COUNTIF(Learning_Data!C:C,"Sales") -> 7 | C4: =COUNTIFS(Learning_Data!C:C,"Sales",Learning_Data!I:I,"Completed") -> 5 | D4: =IF(B4=0,0,C4/B4*100) -> 71.428571
A5: Operations | B5: =COUNTIF(Learning_Data!C:C,"Operations") -> 4 | C5: =COUNTIFS(Learning_Data!C:C,"Operations",Learning_Data!I:I,"Completed") -> 3 | D5: =IF(B5=0,0,C5/B5*100) -> 75
A6: HR | B6: =COUNTIF(Learning_Data!C:C,"HR") -> 10 | C6: =COUNTIFS(Learning_Data!C:C,"HR",Learning_Data!I:I,"Completed") -> 8 | D6: =IF(B6=0,0,C6/B6*100) -> 80
A7: Finance | B7: =COUNTIF(Learning_Data!C:C,"Finance") -> 5 | C7: =COUNTIFS(Learning_Data!C:C,"Finance",Learning_Data!I:I,"Completed") -> 4 | D7: =IF(B7=0,0,C7/B7*100) -> 80
A8: IT | B8: =COUNTIF(Learning_Data!C:C,"IT") -> 9 | C8: =COUNTIFS(Learning_Data!C:C,"IT",Learning_Data!I:I,"Completed") -> 6 | D8: =IF(B8=0,0,C8/B8*100) -> 66.666667
A9: Marketing | B9: =COUNTIF(Learning_Data!C:C,"Marketing") -> 8 | C9: =COUNTIFS(Learning_Data!C:C,"Marketing",Learning_Data!I:I,"Completed") -> 5 | D9: =IF(B9=0,0,C9/B9*100) -> 62.5
A10: Supply Chain | B10: =COUNTIF(Learning_Data!C:C,"Supply Chain") -> 7 | C10: =COUNTIFS(Learning_Data!C:C,"Supply Chain",Learning_Data!I:I,"Completed") -> 6 | D10: =IF(B10=0,0,C10/B10*100) -> 85.714286
